### **Using `begin`, `rescue`, and `ensure` in Ruby**

In Ruby, the `begin`, `rescue`, and `ensure` blocks are used for exception handling. These blocks allow you to manage errors that occur during the execution of a program and ensure proper cleanup of resources, regardless of whether an error occurs.

Here's a breakdown of how each component works:

- **`begin`**: Marks the start of a block of code where exceptions may occur.
- **`rescue`**: Catches exceptions raised inside the `begin` block and allows you to handle them.
- **`ensure`**: Ensures that some code always runs, regardless of whether an exception was raised or not.

---

### **Basic Syntax**

```ruby
begin
  # Code that may raise an exception
rescue SomeExceptionType => e
  # Handle the exception
else
  # Code to run if no exception occurs
ensure
  # Code that always runs (cleanup, closing files, etc.)
end
```

---

### **1. `begin`...`rescue` Example**

The `begin` block contains the code that might raise an exception, and the `rescue` block catches the exception and handles it.

#### **Example: Basic Exception Handling with `begin` and `rescue`**

```ruby
begin
  # Code that may raise an error
  x = 10 / 0  # Dividing by zero raises ZeroDivisionError
rescue ZeroDivisionError => e
  # Handle the exception
  puts "Error: #{e.message}"  # Output: Error: divided by 0
end
```

**Explanation**:
- The `begin` block attempts to divide by zero, which raises a `ZeroDivisionError`.
- The `rescue` block catches the exception and prints an error message.

---

### **2. `begin`...`rescue`...`else` Example**

The `else` block is executed only if no exceptions were raised in the `begin` block.

#### **Example: Using `else`**

```ruby
begin
  # Code that may raise an error
  x = 10 / 2  # No error
rescue ZeroDivisionError => e
  # Handle the exception
  puts "Error: #{e.message}"
else
  # Code to run if no exception occurs
  puts "The result is #{x}"  # Output: The result is 5
end
```

**Explanation**:
- Since no exception occurs in the `begin` block (division by 2 is successful), the `else` block is executed, and it prints the result of the division.

---

### **3. `begin`...`rescue`...`ensure` Example**

The `ensure` block is always executed, no matter what. Itâ€™s typically used for cleanup tasks, such as closing files or releasing resources.

#### **Example: Using `ensure`**

```ruby
begin
  # Code that may raise an error
  file = File.open('example.txt', 'r')  # Open file for reading
  # Simulating an error (uncomment the line below to see the error handling)
  # x = 10 / 0
rescue IOError => e
  # Handle the IOError
  puts "Error: #{e.message}"
ensure
  # Cleanup code (always runs)
  file.close if file
  puts "File has been closed."  # Output: File has been closed.
end
```

**Explanation**:
- The `begin` block tries to open a file and perform an operation. If an `IOError` occurs (e.g., file not found), the `rescue` block will catch the error.
- Regardless of whether an error occurs, the `ensure` block will execute, ensuring the file is closed and a cleanup message is printed.

---

### **4. Raising Exceptions with `raise`**

You can also use the `raise` keyword inside the `begin` block to manually raise an exception.

#### **Example: Raising an Exception Inside `begin`**

```ruby
begin
  raise "Something went wrong!"  # Manually raise an exception
rescue => e
  puts "Caught an exception: #{e.message}"  # Output: Caught an exception: Something went wrong!
ensure
  puts "This will always run"
end
```

**Explanation**:
- The `raise` keyword is used to manually raise an exception inside the `begin` block.
- The `rescue` block catches the exception and handles it by printing a message.
- The `ensure` block runs regardless of whether an exception is raised or not.

---

### **5. Multiple `rescue` Blocks**

You can have multiple `rescue` blocks to handle different types of exceptions separately.

#### **Example: Multiple `rescue` Blocks**

```ruby
begin
  # Code that may raise different types of exceptions
  x = 10 / 0  # ZeroDivisionError
  y = 'a' + 1  # TypeError
rescue ZeroDivisionError => e
  puts "Caught a division error: #{e.message}"
rescue TypeError => e
  puts "Caught a type error: #{e.message}"
else
  puts "No errors occurred"
ensure
  puts "Execution completed"
end
```

**Explanation**:
- The `ZeroDivisionError` is caught first, and its message is printed.
- If a `TypeError` had been raised, it would have been caught by the second `rescue` block.
- The `ensure` block always runs.

**Output**:
```
Caught a division error: divided by 0
Execution completed
```

---

### **6. Custom Exceptions**

You can create custom exceptions by defining your own exception classes.

#### **Example: Custom Exception Class**

```ruby
class MyCustomError < StandardError
  def initialize(msg="Custom error occurred")
    super(msg)
  end
end

begin
  raise MyCustomError.new("Something went wrong with my custom error!")
rescue MyCustomError => e
  puts "Caught a custom error: #{e.message}"  # Output: Caught a custom error: Something went wrong with my custom error!
ensure
  puts "This will always run"
end
```

**Explanation**:
- A custom exception `MyCustomError` is defined, inheriting from `StandardError`.
- The `raise` keyword raises this custom exception, and the `rescue` block catches it.

---

### **Conclusion**

Ruby's exception handling with `begin`, `rescue`, and `ensure` allows you to handle errors in a structured way. You can catch specific errors, execute alternative code, and ensure cleanup happens even in the case of an error.

- **`begin`**: Wraps code that may raise an exception.
- **`rescue`**: Catches exceptions and provides error handling.
- **`ensure`**: Executes code that should run regardless of an error (for cleanup).
- **`else`**: Executes if no exception occurs in the `begin` block.
