**Exception handling** in Java is a mechanism to handle runtime errors gracefully, ensuring that the program can continue executing or terminate cleanly. The primary constructs for exception handling are `try`, `catch`, and `finally`. Let’s explore these in detail.

---

### **1. Basics of Exception Handling**
- **Exception**: An event that disrupts the normal flow of the program.
- **Checked Exceptions**: Exceptions that are checked at compile time (e.g., `IOException`, `SQLException`).
- **Unchecked Exceptions**: Exceptions that are checked at runtime (e.g., `NullPointerException`, `ArithmeticException`).

---

### **2. `try` Block**
The `try` block contains code that might throw an exception. It must be followed by at least one `catch` block or a `finally` block.

#### **Syntax**:
```java
try {
    // Code that might throw an exception
} catch (ExceptionType e) {
    // Handle the exception
} finally {
    // Code that always executes
}
```

---

### **3. `catch` Block**
The `catch` block handles the exception thrown by the `try` block. You can have multiple `catch` blocks to handle different types of exceptions.

#### **Syntax**:
```java
catch (ExceptionType e) {
    // Handle the exception
}
```

#### **Example**:
```java
public class Main {
    public static void main(String[] args) {
        try {
            int result = 10 / 0; // ArithmeticException
        } catch (ArithmeticException e) {
            System.out.println("Exception caught: " + e.getMessage());
        }
    }
}
```
**Output**:
```
Exception caught: / by zero
```

---

### **4. `finally` Block**
The `finally` block is used to execute code that must run regardless of whether an exception occurs. It is often used for cleanup activities (e.g., closing files, releasing resources).

#### **Syntax**:
```java
finally {
    // Code that always executes
}
```

#### **Example**:
```java
public class Main {
    public static void main(String[] args) {
        try {
            int result = 10 / 0; // ArithmeticException
        } catch (ArithmeticException e) {
            System.out.println("Exception caught: " + e.getMessage());
        } finally {
            System.out.println("Finally block executed.");
        }
    }
}
```
**Output**:
```
Exception caught: / by zero
Finally block executed.
```

---

### **5. Multiple `catch` Blocks**
You can have multiple `catch` blocks to handle different types of exceptions. The first matching `catch` block is executed.

#### **Example**:
```java
public class Main {
    public static void main(String[] args) {
        try {
            int[] numbers = {1, 2, 3};
            System.out.println(numbers[5]); // ArrayIndexOutOfBoundsException
        } catch (ArithmeticException e) {
            System.out.println("ArithmeticException caught: " + e.getMessage());
        } catch (ArrayIndexOutOfBoundsException e) {
            System.out.println("ArrayIndexOutOfBoundsException caught: " + e.getMessage());
        } finally {
            System.out.println("Finally block executed.");
        }
    }
}
```
**Output**:
```
ArrayIndexOutOfBoundsException caught: Index 5 out of bounds for length 3
Finally block executed.
```

---

### **6. Nested `try-catch` Blocks**
You can nest `try-catch` blocks to handle exceptions at different levels of code.

#### **Example**:
```java
public class Main {
    public static void main(String[] args) {
        try {
            try {
                int result = 10 / 0; // ArithmeticException
            } catch (ArithmeticException e) {
                System.out.println("Inner catch: " + e.getMessage());
            }
            int[] numbers = {1, 2, 3};
            System.out.println(numbers[5]); // ArrayIndexOutOfBoundsException
        } catch (ArrayIndexOutOfBoundsException e) {
            System.out.println("Outer catch: " + e.getMessage());
        } finally {
            System.out.println("Finally block executed.");
        }
    }
}
```
**Output**:
```
Inner catch: / by zero
Outer catch: Index 5 out of bounds for length 3
Finally block executed.
```

---

### **7. `try-with-resources`**
The `try-with-resources` statement automatically closes resources (e.g., files, sockets) that implement the `AutoCloseable` interface.

#### **Syntax**:
```java
try (ResourceType resource = new ResourceType()) {
    // Use the resource
} catch (Exception e) {
    // Handle the exception
}
```

#### **Example**:
```java
import java.io.FileInputStream;
import java.io.IOException;

public class Main {
    public static void main(String[] args) {
        try (FileInputStream fis = new FileInputStream("file.txt")) {
            int data = fis.read();
            while (data != -1) {
                System.out.print((char) data);
                data = fis.read();
            }
        } catch (IOException e) {
            System.out.println("Exception caught: " + e.getMessage());
        }
    }
}
```

---

### **8. Custom Exceptions**
You can create your own exceptions by extending the `Exception` class.

#### **Example**:
```java
class MyException extends Exception {
    public MyException(String message) {
        super(message);
    }
}

public class Main {
    public static void main(String[] args) {
        try {
            throw new MyException("This is a custom exception.");
        } catch (MyException e) {
            System.out.println("Custom exception caught: " + e.getMessage());
        }
    }
}
```
**Output**:
```
Custom exception caught: This is a custom exception.
```

---

### **9. Example Program**
Here’s a complete example demonstrating exception handling with `try`, `catch`, and `finally`:

```java
public class Main {
    public static void main(String[] args) {
        try {
            int[] numbers = {1, 2, 3};
            System.out.println(numbers[5]); // ArrayIndexOutOfBoundsException
        } catch (ArithmeticException e) {
            System.out.println("ArithmeticException caught: " + e.getMessage());
        } catch (ArrayIndexOutOfBoundsException e) {
            System.out.println("ArrayIndexOutOfBoundsException caught: " + e.getMessage());
        } finally {
            System.out.println("Finally block executed.");
        }
    }
}
```
**Output**:
```
ArrayIndexOutOfBoundsException caught: Index 5 out of bounds for length 3
Finally block executed.
```

---

### **Conclusion**
Exception handling is a critical aspect of Java programming that ensures your programs can handle errors gracefully. By using `try`, `catch`, and `finally` blocks, you can manage runtime exceptions, perform cleanup operations, and maintain the stability of your applications. Whether you're working with built-in exceptions or creating custom ones, mastering exception handling is essential for writing robust Java code.
