### **Try, Catch, and Throw Mechanisms in C++**

In C++, **exception handling** is used to deal with runtime errors or exceptional conditions that may arise during the execution of a program. The **try**, **catch**, and **throw** mechanisms are fundamental components of this process, which help you detect and handle errors gracefully without crashing the program.

Hereâ€™s a breakdown of how each of these components works:

### 1. **`throw` - Throwing an Exception**
   - The `throw` keyword is used to **throw an exception** when a certain condition is met (usually an error or an unexpected situation).
   - When an exception is thrown, the control of the program is transferred to the nearest **catch block** that can handle the exception.
   - Exceptions can be of any type (objects, primitive types, etc.), but it is common to use objects derived from the `std::exception` class.

   **Syntax**:
   ```cpp
   throw exception_object; // throwing an exception object
   throw value;             // throwing a value (e.g., int, string)
   ```

   **Example**:
   ```cpp
   if (num == 0) {
       throw "Division by zero error"; // Throwing a string literal as an exception
   }
   ```

### 2. **`try` - Code That May Throw an Exception**
   - The `try` block contains the code that might throw an exception. This is the section of the program where you expect something might go wrong, such as division by zero, invalid input, memory allocation failure, etc.
   - If an exception is thrown inside the `try` block, the control is transferred to the corresponding `catch` block, if one exists.

   **Syntax**:
   ```cpp
   try {
       // code that might throw an exception
   }
   ```

   **Example**:
   ```cpp
   try {
       int result = divide(a, b); // Calling a function that might throw an exception
   }
   ```

### 3. **`catch` - Catching and Handling Exceptions**
   - The `catch` block is used to **handle exceptions** that were thrown inside the `try` block. You can have multiple `catch` blocks to handle different types of exceptions.
   - The `catch` block catches the exception thrown by the `throw` statement and allows the program to handle the error, either by logging the error, taking corrective actions, or terminating gracefully.
   - A `catch` block must match the type of the thrown exception.

   **Syntax**:
   ```cpp
   catch (ExceptionType& e) {
       // Handle the exception
   }
   ```

   **Example**:
   ```cpp
   catch (const char* msg) {
       cout << "Error: " << msg << endl;
   }
   ```

### **Complete Example with `try`, `catch`, and `throw`**

```cpp
#include <iostream>
using namespace std;

// Function that throws an exception when dividing by zero
int divide(int a, int b) {
    if (b == 0) {
        throw "Division by zero error";  // Throwing an exception
    }
    return a / b;
}

int main() {
    int x = 10, y = 0;

    try {
        // Trying to divide by zero
        int result = divide(x, y);
        cout << "Result: " << result << endl;
    }
    catch (const char* msg) {
        // Catching the exception and handling it
        cout << "Caught exception: " << msg << endl;
    }

    return 0;
}
```

### **Explanation**:
1. **`divide()` function**:
   - This function checks if `b` (the divisor) is zero. If it is, it **throws an exception** using `throw "Division by zero error"`.
   - If no error occurs, the function returns the result of the division.

2. **`try` block**:
   - The `try` block calls the `divide(x, y)` function.
   - If an exception is thrown (like dividing by zero), control is transferred to the corresponding `catch` block.

3. **`catch` block**:
   - The `catch` block catches the thrown exception (in this case, a string) and prints an error message.

### **Multiple Catch Blocks**

You can have multiple `catch` blocks to handle different types of exceptions. For example, one for standard exceptions, another for integers, or other custom exceptions.

**Example of Multiple Catch Blocks**:

```cpp
#include <iostream>
using namespace std;

void process(int num) {
    if (num == 0) {
        throw "Cannot divide by zero!";
    }
    else if (num < 0) {
        throw 101;  // Throwing an integer as an exception
    }
    else {
        cout << "Number is positive" << endl;
    }
}

int main() {
    try {
        process(0);  // Will throw a string exception
    }
    catch (const char* msg) {
        cout << "Caught error: " << msg << endl;
    }

    try {
        process(-1);  // Will throw an integer exception
    }
    catch (int errorCode) {
        cout << "Caught error code: " << errorCode << endl;
    }

    return 0;
}
```

### **Explanation**:
- The first `try` block catches the exception of type `const char*`, which is thrown when `num` is zero.
- The second `try` block catches an integer exception, thrown when `num` is negative.

### **Exception Propagation**

If an exception is thrown but not caught in the current function, it **propagates** up the call stack to the calling function. This means that the calling function will look for a `catch` block to handle the exception.

**Example of Exception Propagation**:

```cpp
#include <iostream>
using namespace std;

void funcA() {
    throw "An error occurred in funcA!";
}

void funcB() {
    funcA();  // Calling funcA, where the exception will be thrown
}

int main() {
    try {
        funcB();  // funcB calls funcA, which throws the exception
    }
    catch (const char* msg) {
        cout << "Caught exception: " << msg << endl;
    }

    return 0;
}
```

### **Explanation**:
- `funcA()` throws an exception.
- `funcB()` calls `funcA()` and does not catch the exception.
- The exception propagates back to the `main()` function, where it is caught and handled.

### **C++ Standard Library Exceptions**

The C++ Standard Library provides a set of predefined exception classes in the `<exception>` header. Some commonly used ones include:

- **`std::exception`**: The base class for all standard exceptions.
- **`std::runtime_error`**: Used for runtime errors.
- **`std::logic_error`**: Used for errors in the logic of the program.
- **`std::out_of_range`**: Thrown when an out-of-range error occurs (e.g., accessing an out-of-bounds index of a container).

**Example with `std::runtime_error`**:

```cpp
#include <iostream>
#include <stdexcept>  // For standard exceptions
using namespace std;

int divide(int a, int b) {
    if (b == 0) {
        throw runtime_error("Division by zero");  // Throwing a runtime error
    }
    return a / b;
}

int main() {
    try {
        int result = divide(10, 0);  // Will throw a runtime_error
    }
    catch (const runtime_error& e) {
        cout << "Caught exception: " << e.what() << endl;  // Accessing the error message
    }

    return 0;
}
```

### **Explanation**:
- Here, the `divide()` function throws a `runtime_error` if division by zero is attempted.
- The exception is caught by the `catch` block, and the error message is printed using the `what()` method of the `std::exception` class.

---

### **Conclusion**

The **try, catch, and throw** mechanisms in C++ are a fundamental part of **exception handling**, allowing you to manage errors gracefully during runtime. These mechanisms enable you to:
- Throw exceptions when errors occur.
- Catch and handle exceptions at different levels of the program.
- Ensure that your program doesn't crash unexpectedly by managing exceptions and taking appropriate actions.

By using exceptions, you can write more robust, maintainable, and user-friendly programs.
